{
    "track_id": "BRt5lzFQ",
    "prompt": "Unknown ERROR->ValueError",
    "time": "2021-08-05 17:21:33",
    "content": "Traceback (most recent call last):\n  File \"D:\\feiBot\\bot\\.\\src\\exceptions.py\", line 103, in _track_error\n    raise exception\n  File \"c:\\users\\hasee\\appdata\\local\\programs\\python\\python39\\lib\\site-packages\\nonebot\\message.py\", line 154, in _run_matcher\n    await matcher.run(bot, event, state)\n  File \"c:\\users\\hasee\\appdata\\local\\programs\\python\\python39\\lib\\site-packages\\nonebot\\matcher.py\", line 544, in run\n    await handler(self, bot, event, state_)\n  File \"c:\\users\\hasee\\appdata\\local\\programs\\python\\python39\\lib\\site-packages\\nonebot\\handler.py\", line 81, in __call__\n    await self.func(\n  File \"D:\\feiBot\\bot\\src/plugins\\setu\\__init__.py\", line 55, in _tag_setu\n    setu, title, p_id, is_ok = await Setu().tag_setu(tag)\nValueError: not enough values to unpack (expected 4, got 3)\n"
}