{
    "track_id": "cvOjXFx0",
    "prompt": "Unknown ERROR->NameError",
    "time": "2021-08-04 09:35:31",
    "content": "Traceback (most recent call last):\n  File \"D:\\feiBot\\bot\\.\\src\\exceptions.py\", line 103, in _track_error\n    raise exception\n  File \"c:\\users\\hasee\\appdata\\local\\programs\\python\\python39\\lib\\site-packages\\nonebot\\message.py\", line 154, in _run_matcher\n    await matcher.run(bot, event, state)\n  File \"c:\\users\\hasee\\appdata\\local\\programs\\python\\python39\\lib\\site-packages\\nonebot\\matcher.py\", line 544, in run\n    await handler(self, bot, event, state_)\n  File \"c:\\users\\hasee\\appdata\\local\\programs\\python\\python39\\lib\\site-packages\\nonebot\\handler.py\", line 81, in __call__\n    await self.func(\n  File \"D:\\feiBot\\bot\\src/plugins\\query\\__init__.py\", line 19, in _random_setu\n    if not _setu_flmt.check(user_id):\nNameError: name '_setu_flmt' is not defined\n"
}