{
    "track_id": "flFY3KIa",
    "prompt": "Unknown ERROR->NameError",
    "time": "2021-08-04 10:42:35",
    "content": "Traceback (most recent call last):\n  File \"D:\\feiBot\\bot\\src/plugins\\query\\data_source.py\", line 29, in add\n    result = dbsession.query(PICS).filter(PICS.name==str(name)).one()\nNameError: name 'name' is not defined\n\nDuring handling of the above exception, another exception occurred:\n\nTraceback (most recent call last):\n  File \"D:\\feiBot\\bot\\src/plugins\\query\\data_source.py\", line 36, in add\n    urllib.request.urlretrieve(img[0], filename=fname)\nNameError: name 'img' is not defined\n\nDuring handling of the above exception, another exception occurred:\n\nTraceback (most recent call last):\n  File \"D:\\feiBot\\bot\\.\\src\\exceptions.py\", line 103, in _track_error\n    raise exception\n  File \"c:\\users\\hasee\\appdata\\local\\programs\\python\\python39\\lib\\site-packages\\nonebot\\message.py\", line 154, in _run_matcher\n    await matcher.run(bot, event, state)\n  File \"c:\\users\\hasee\\appdata\\local\\programs\\python\\python39\\lib\\site-packages\\nonebot\\matcher.py\", line 544, in run\n    await handler(self, bot, event, state_)\n  File \"c:\\users\\hasee\\appdata\\local\\programs\\python\\python39\\lib\\site-packages\\nonebot\\handler.py\", line 81, in __call__\n    await self.func(\n  File \"c:\\users\\hasee\\appdata\\local\\programs\\python\\python39\\lib\\site-packages\\nonebot\\matcher.py\", line 427, in wrapper\n    await func_handler(matcher, bot, event, state)\n  File \"c:\\users\\hasee\\appdata\\local\\programs\\python\\python39\\lib\\site-packages\\nonebot\\handler.py\", line 81, in __call__\n    await self.func(\n  File \"D:\\feiBot\\bot\\src/plugins\\query\\__init__.py\", line 55, in _deal_add\n    result = await a.add(img[0])\n  File \"D:\\feiBot\\bot\\src/plugins\\query\\data_source.py\", line 44, in add\n    session.state[session.current_key] = '\u51fa\u9519\u5566'\nNameError: name 'session' is not defined\n"
}