{
    "track_id": "JgfAwETC",
    "prompt": "Unknown ERROR->IndexError",
    "time": "2021-08-05 16:58:08",
    "content": "Traceback (most recent call last):\n  File \"D:\\feiBot\\bot\\.\\src\\exceptions.py\", line 103, in _track_error\n    raise exception\n  File \"c:\\users\\hasee\\appdata\\local\\programs\\python\\python39\\lib\\site-packages\\nonebot\\message.py\", line 154, in _run_matcher\n    await matcher.run(bot, event, state)\n  File \"c:\\users\\hasee\\appdata\\local\\programs\\python\\python39\\lib\\site-packages\\nonebot\\matcher.py\", line 544, in run\n    await handler(self, bot, event, state_)\n  File \"c:\\users\\hasee\\appdata\\local\\programs\\python\\python39\\lib\\site-packages\\nonebot\\handler.py\", line 81, in __call__\n    await self.func(\n  File \"D:\\feiBot\\bot\\src/plugins\\setu\\__init__.py\", line 52, in _tag_setu\n    setu, title, p_id, is_ok = await Setu().tag_setu(tag)\n  File \"D:\\feiBot\\bot\\src/plugins\\setu\\data_source.py\", line 48, in tag_setu\n    temp_data: dict = data.get(\"data\", list())[0]\nIndexError: list index out of range\n"
}