{
    "track_id": "OuRnH67E",
    "prompt": "Unknown ERROR->AttributeError",
    "time": "2021-09-05 14:09:26",
    "content": "Traceback (most recent call last):\n  File \"D:\\feiBot\\bot\\.\\src\\exceptions.py\", line 103, in _track_error\n    raise exception\n  File \"c:\\users\\hasee\\appdata\\local\\programs\\python\\python39\\lib\\site-packages\\nonebot\\message.py\", line 154, in _run_matcher\n    await matcher.run(bot, event, state)\n  File \"c:\\users\\hasee\\appdata\\local\\programs\\python\\python39\\lib\\site-packages\\nonebot\\matcher.py\", line 544, in run\n    await handler(self, bot, event, state_)\n  File \"c:\\users\\hasee\\appdata\\local\\programs\\python\\python39\\lib\\site-packages\\nonebot\\handler.py\", line 81, in __call__\n    await self.func(\n  File \"D:\\feiBot\\bot\\src/plugins\\test\\__init__.py\", line 25, in test\n    await test.finish('Done.\u8bf7\u67e5\u770b\u63a7\u5236\u53f0.')\nAttributeError: 'function' object has no attribute 'finish'\n"
}