{
    "track_id": "xSID1EZW",
    "prompt": "Unknown ERROR->TypeError",
    "time": "2021-08-06 16:03:01",
    "content": "Traceback (most recent call last):\n  File \"D:\\feiBot\\bot\\.\\src\\exceptions.py\", line 103, in _track_error\n    raise exception\n  File \"c:\\users\\hasee\\appdata\\local\\programs\\python\\python39\\lib\\site-packages\\nonebot\\message.py\", line 154, in _run_matcher\n    await matcher.run(bot, event, state)\n  File \"c:\\users\\hasee\\appdata\\local\\programs\\python\\python39\\lib\\site-packages\\nonebot\\matcher.py\", line 544, in run\n    await handler(self, bot, event, state_)\n  File \"c:\\users\\hasee\\appdata\\local\\programs\\python\\python39\\lib\\site-packages\\nonebot\\handler.py\", line 81, in __call__\n    await self.func(\n  File \"D:\\feiBot\\bot\\src/plugins\\funny\\__init__.py\", line 17, in _get_laugh\n    await get_laugh.finish(await Funny().idk_laugh(user_name))\n  File \"D:\\feiBot\\bot\\src/plugins\\funny\\data_source.py\", line 41, in idk_laugh\n    context = await res.text()  # type: ignore\nTypeError: 'coroutine' object is not callable\n"
}